<?xml version = "1.0"?>
<robot
  name="dancer_urdf_model">
<!-- root link -->
  <link 
    name="world_link">
  </link>
  <joint 
    name="joint_world" type="fixed">
    <parent link="world_link"/>
    <child link="body_chest"/>
  </joint>
<!-- body -->
  <link
    name="body_chest">
    <inertial>
      <origin
        xyz="-0.39529 -0.25795 -0.0041722"
        rpy="0 0 0" />
      <mass
        value="0.66907" />
      <inertia
        ixx="0.0010789"
        ixy="-2.1492E-06"
        ixz="-1.1578E-06"
        iyy="0.0012519"
        iyz="0.00017837"
        izz="0.0014192" />
    </inertial>
    <visual>
      <origin
        xyz="0 0 0"
        rpy="0 0 0" />
      <geometry>
        <mesh
          filename="package://dancer_urdf_model/meshes/body_chest.STL" />
      </geometry>
      <material
        name="">
        <color
          rgba="0.75294 0.75294 0.75294 1" />
      </material>
    </visual>
    <collision>
      <origin
        xyz="0 0 0"
        rpy="0 0 0" />
      <geometry>
        <mesh
          filename="package://dancer_urdf_model/meshes/body_chest.STL" />
      </geometry>
    </collision>
  </link>
  <link
    name="body_head">
    <inertial>
      <origin
        xyz="-0.000351851554432403 -0.0159432418124996 -6.20136945961303E-09"
        rpy="0 0 0" />
      <mass
        value="0.0560380421735799" />
      <inertia
        ixx="6.80542660516315E-06"
        ixy="2.52790190769969E-07"
        ixz="2.16353945279601E-13"
        iyy="1.50295053154063E-06"
        iyz="1.49161003758429E-12"
        izz="8.30837713670273E-06" />
    </inertial>
    <visual>
      <origin
        xyz="0 0 0"
        rpy="0 0 0" />
      <geometry>
        <mesh
          filename="package://dancer_urdf_model/meshes/body_head.STL" />
      </geometry>
      <material
        name="">
        <color
          rgba="0.866666666666667 0.909803921568627 1 1" />
      </material>
    </visual>
    <collision>
      <origin
        xyz="0 0 0"
        rpy="0 0 0" />
      <geometry>
        <mesh
          filename="package://dancer_urdf_model/meshes/body_head.STL" />
      </geometry>
    </collision>
  </link>
  <joint
    name="joint_body_head"
    type="continuous">
    <origin
      xyz="-0.39482 -0.32209 -0.014452"
      rpy="2.6872 -0.050522 -3.1169" />
    <parent
      link="body_chest" />
    <child
      link="body_head" />
    <axis
      xyz="0 1 0" />
    <dynamics
      damping="0.0"
      friction="0.0" />
  </joint>
  <link
    name="body_head2">
    <inertial>
      <origin
        xyz="-0.020399 -0.025987 -0.047171"
        rpy="0 0 0" />
      <mass
        value="0.067365" />
      <inertia
        ixx="2.0873E-05"
        ixy="2.2756E-10"
        ixz="9.0633E-10"
        iyy="6.1663E-06"
        iyz="-4.8418E-06"
        izz="1.4707E-05" />
    </inertial>
    <visual>
      <origin
        xyz="0 0 0"
        rpy="0 0 0" />
      <geometry>
        <mesh
          filename="package://dancer_urdf_model/meshes/body_head2.STL" />
      </geometry>
      <material
        name="">
        <color
          rgba="0.25098 0.25098 0.25098 1" />
      </material>
    </visual>
    <collision>
      <origin
        xyz="0 0 0"
        rpy="0 0 0" />
      <geometry>
        <mesh
          filename="package://dancer_urdf_model/meshes/body_head2.STL" />
      </geometry>
    </collision>
  </link>
  <joint
    name="joint_body_head2"
    type="continuous">
    <origin
      xyz="0.02015 -0.031182 0"
      rpy="-1.1164 0 0" />
    <parent
      link="body_head" />
    <child
      link="body_head2" />
    <axis
      xyz="-1 0 0" />
    <dynamics
      damping="0.0"
      friction="0.0" />
  </joint>
  <link
    name="arm_left">
    <inertial>
      <origin
        xyz="0.00185814795587239 -0.0815728051955473 0.0294005743652034"
        rpy="0 0 0" />
      <mass
        value="0.142976459032186" />
      <inertia
        ixx="0.000249420588469075"
        ixy="7.32525652321763E-06"
        ixz="7.10318603096419E-06"
        iyy="5.00248806790026E-05"
        iyz="-1.63332458191431E-05"
        izz="0.000260415991235315" />
    </inertial>
    <visual>
      <origin
        xyz="0 0 0"
        rpy="0 0 0" />
      <geometry>
        <mesh
          filename="package://dancer_urdf_model/meshes/arm_left.STL" />
      </geometry>
      <material
        name="">
        <color
          rgba="1 1 1 1" />
      </material>
    </visual>
    <collision>
      <origin
        xyz="0 0 0"
        rpy="0 0 0" />
      <geometry>
        <mesh
          filename="package://dancer_urdf_model/meshes/arm_left.STL" />
      </geometry>
    </collision>
  </link>
  <joint
    name="joint_arm_left"
    type="continuous">
    <origin
      xyz="-0.46902 -0.2921 0.00017561"
      rpy="-1.5708 -0.59813 1.5708" />
    <parent
      link="body_chest" />
    <child
      link="arm_left" />
    <axis
      xyz="0 0 1" />
    <dynamics
      damping="0.0"
      friction="0.0" />
  </joint>
  <link
    name="hand_left">
    <inertial>
      <origin
        xyz="-0.00150000000000006 0.0513998176588075 -0.0471166731147821"
        rpy="0 0 0" />
      <mass
        value="0.021948273112724" />
      <inertia
        ixx="0"
        ixy="0"
        ixz="0"
        iyy="0"
        iyz="0"
        izz="0" />
    </inertial>
    <visual>
      <origin
        xyz="0 0 0"
        rpy="0 0 0" />
      <geometry>
        <mesh
          filename="package://dancer_urdf_model/meshes/hand_left.STL" />
      </geometry>
      <material
        name="">
        <color
          rgba="1 1 1 1" />
      </material>
    </visual>
    <collision>
      <origin
        xyz="0 0 0"
        rpy="0 0 0" />
      <geometry>
        <mesh
          filename="package://dancer_urdf_model/meshes/hand_left.STL" />
      </geometry>
    </collision>
  </link>
  <joint
    name="joint_hand_left"
    type="continuous">
    <origin
      xyz="0 -0.136 0.05255"
      rpy="0.59813 -1.5708 0" />
    <parent
      link="arm_left" />
    <child
      link="hand_left" />
    <axis
      xyz="1 0 0" />
    <dynamics
      damping="0.0"
      friction="0.0" />
  </joint>
  <link
    name="arm_right">
    <inertial>
      <origin
        xyz="0.00187545595097149 -0.0810657497418857 0.0317817660201292"
        rpy="0 0 0" />
      <mass
        value="0.141656759847187" />
      <inertia
        ixx="0.000244964545549609"
        ixy="7.19058779167484E-06"
        ixz="-7.15162953626525E-06"
        iyy="4.95100328023302E-05"
        iyz="1.49143124694347E-05"
        izz="0.000256465619549068" />
    </inertial>
    <visual>
      <origin
        xyz="0 0 0"
        rpy="0 0 0" />
      <geometry>
        <mesh
          filename="package://dancer_urdf_model/meshes/arm_right.STL" />
      </geometry>
      <material
        name="">
        <color
          rgba="0.898039215686275 0.917647058823529 0.929411764705882 1" />
      </material>
    </visual>
    <collision>
      <origin
        xyz="0 0 0"
        rpy="0 0 0" />
      <geometry>
        <mesh
          filename="package://dancer_urdf_model/meshes/arm_right.STL" />
      </geometry>
    </collision>
  </link>
  <joint
    name="joint_arm_right"
    type="continuous">
    <origin
      xyz="-0.25942 -0.2921 0.00017561"
      rpy="-1.5708 1.0373 1.5708" />
    <parent
      link="body_chest" />
    <child
      link="arm_right" />
    <axis
      xyz="0 0 1" />
    <dynamics
      damping="0.0"
      friction="0.0" />
  </joint>
  <link
    name="hand_right">
    <inertial>
      <origin
        xyz="-0.00150000000000061 -0.0550818675496146 -0.0427540642279834"
        rpy="0 0 0" />
      <mass
        value="0.021948273112724" />
      <inertia
        ixx="0"
        ixy="0"
        ixz="0"
        iyy="0"
        iyz="0"
        izz="0" />
    </inertial>
    <visual>
      <origin
        xyz="0 0 0"
        rpy="0 0 0" />
      <geometry>
        <mesh
          filename="package://dancer_urdf_model/meshes/hand_right.STL" />
      </geometry>
      <material
        name="">
        <color
          rgba="1 1 1 1" />
      </material>
    </visual>
    <collision>
      <origin
        xyz="0 0 0"
        rpy="0 0 0" />
      <geometry>
        <mesh
          filename="package://dancer_urdf_model/meshes/hand_right.STL" />
      </geometry>
    </collision>
  </link>
  <joint
    name="joint_hand_right"
    type="continuous">
    <origin
      xyz="0 -0.136 0.00845"
      rpy="2.1043 1.5708 0" />
    <parent
      link="arm_right" />
    <child
      link="hand_right" />
    <axis
      xyz="1 0 0" />
    <dynamics
      damping="0.0"
      friction="0.0" />
  </joint>
  <link
    name="body_hip">
    <inertial>
      <origin
        xyz="0.000157245394557526 0.0183365350270815 0.0512514015755213"
        rpy="0 0 0" />
      <mass
        value="0.220741166410594" />
      <inertia
        ixx="4.99532905906753E-05"
        ixy="-8.8425558025927E-07"
        ixz="4.63751185231834E-07"
        iyy="0.000349635027414184"
        iyz="-8.11153973374568E-06"
        izz="0.000393338670951652" />
    </inertial>
    <visual>
      <origin
        xyz="0 0 0"
        rpy="0 0 0" />
      <geometry>
        <mesh
          filename="package://dancer_urdf_model/meshes/body_hip.STL" />
      </geometry>
      <material
        name="">
        <color
          rgba="0.752941176470588 0.752941176470588 0.752941176470588 1" />
      </material>
    </visual>
    <collision>
      <origin
        xyz="0 0 0"
        rpy="0 0 0" />
      <geometry>
        <mesh
          filename="package://dancer_urdf_model/meshes/body_hip.STL" />
      </geometry>
    </collision>
  </link>
  <joint
    name="joint_body_hip"
    type="continuous">
    <origin
      xyz="-0.39482 -0.11668 0.01337"
      rpy="-0.45379 0 -3.1416" />
    <parent
      link="body_chest" />
    <child
      link="body_hip" />
    <axis
      xyz="0 1 0" />
    <dynamics
      damping="0.0"
      friction="0.0" />
  </joint>
  <link
    name="body_hip_left">
    <inertial>
      <origin
        xyz="0.020727573256466 0.00401171130451616 -0.000185064805642399"
        rpy="0 0 0" />
      <mass
        value="0.0513468076618724" />
      <inertia
        ixx="5.53880436537222E-07"
        ixy="9.93497455590853E-07"
        ixz="-4.44878455701968E-08"
        iyy="5.30575756787479E-06"
        iyz="-2.18432738949885E-09"
        izz="5.33896357399273E-06" />
    </inertial>
    <visual>
      <origin
        xyz="0 0 0"
        rpy="0 0 0" />
      <geometry>
        <mesh
          filename="package://dancer_urdf_model/meshes/body_hip_left.STL" />
      </geometry>
      <material
        name="">
        <color
          rgba="0.776470588235294 0.756862745098039 0.737254901960784 1" />
      </material>
    </visual>
    <collision>
      <origin
        xyz="0 0 0"
        rpy="0 0 0" />
      <geometry>
        <mesh
          filename="package://dancer_urdf_model/meshes/body_hip_left.STL" />
      </geometry>
    </collision>
  </link>
  <joint
    name="joint_body_hip_left"
    type="continuous">
    <origin
      xyz="0.045 -0.0122 0.065"
      rpy="1.5708 0 -1.5708" />
    <parent
      link="body_hip" />
    <child
      link="body_hip_left" />
    <axis
      xyz="-1 0 0" />
    <dynamics
      damping="0.0"
      friction="0.0" />
  </joint>
  <link
    name="body_hip2_left">
    <inertial>
      <origin
        xyz="-0.05214771499803 -0.0126151296156827 0.000799339990500914"
        rpy="0 0 0" />
      <mass
        value="0.178226116015845" />
      <inertia
        ixx="1.31915893268092E-05"
        ixy="1.10728342854583E-05"
        ixz="-3.64501965445685E-07"
        iyy="0.00014636948190844"
        iyz="4.48899648606397E-07"
        izz="0.000142732199426348" />
    </inertial>
    <visual>
      <origin
        xyz="0 0 0"
        rpy="0 0 0" />
      <geometry>
        <mesh
          filename="package://dancer_urdf_model/meshes/body_hip2_left.STL" />
      </geometry>
      <material
        name="">
        <color
          rgba="0.752941176470588 0.752941176470588 0.752941176470588 1" />
      </material>
    </visual>
    <collision>
      <origin
        xyz="0 0 0"
        rpy="0 0 0" />
      <geometry>
        <mesh
          filename="package://dancer_urdf_model/meshes/body_hip2_left.STL" />
      </geometry>
    </collision>
  </link>
  <joint
    name="joint_body_hip2_left"
    type="continuous">
    <origin
      xyz="0.0493 0.033966 -0.0015267"
      rpy="3.0498 0.044917 1.5708" />
    <parent
      link="body_hip_left" />
    <child
      link="body_hip2_left" />
    <axis
      xyz="-1 0 0" />
    <dynamics
      damping="0.0"
      friction="0.0" />
  </joint>
  <link
    name="leg_left">
    <inertial>
      <origin
        xyz="-0.0239762815919513 0.0733271184441349 -0.0492320368464383"
        rpy="0 0 0" />
      <mass
        value="0.117898503490257" />
      <inertia
        ixx="8.19638344105388E-05"
        ixy="4.15735753169954E-07"
        ixz="-3.08942552253119E-07"
        iyy="5.79765950100758E-05"
        iyz="-3.98771822899511E-05"
        izz="7.68071497117597E-05" />
    </inertial>
    <visual>
      <origin
        xyz="0 0 0"
        rpy="0 0 0" />
      <geometry>
        <mesh
          filename="package://dancer_urdf_model/meshes/leg_left.STL" />
      </geometry>
      <material
        name="">
        <color
          rgba="0.752941176470588 0.752941176470588 0.752941176470588 1" />
      </material>
    </visual>
    <collision>
      <origin
        xyz="0 0 0"
        rpy="0 0 0" />
      <geometry>
        <mesh
          filename="package://dancer_urdf_model/meshes/leg_left.STL" />
      </geometry>
    </collision>
  </link>
  <joint
    name="joint_leg_left"
    type="continuous">
    <origin
      xyz="-0.034 0.0013682 0.024061"
      rpy="-2.6864 -1.514 1.5708" />
    <parent
      link="body_hip2_left" />
    <child
      link="leg_left" />
    <axis
      xyz="-1 0 0" />
    <dynamics
      damping="0.0"
      friction="0.0" />
  </joint>
  <link
    name="leg2_left">
    <inertial>
      <origin
        xyz="-0.0235000000000001 0.0561541813174893 0.0270927391440708"
        rpy="0 0 0" />
      <mass
        value="0.0278306854029525" />
      <inertia
        ixx="2.00646228342237E-06"
        ixy="1.74773182168739E-20"
        ixz="-1.11173074327127E-21"
        iyy="1.45608552327633E-05"
        iyz="-5.34162892350515E-08"
        izz="1.65644713873633E-05" />
    </inertial>
    <visual>
      <origin
        xyz="0 0 0"
        rpy="0 0 0" />
      <geometry>
        <mesh
          filename="package://dancer_urdf_model/meshes/leg2_left.STL" />
      </geometry>
      <material
        name="">
        <color
          rgba="0.866666666666667 0.909803921568627 1 1" />
      </material>
    </visual>
    <collision>
      <origin
        xyz="0 0 0"
        rpy="0 0 0" />
      <geometry>
        <mesh
          filename="package://dancer_urdf_model/meshes/leg2_left.STL" />
      </geometry>
    </collision>
  </link>
  <joint
    name="joint_leg2_left"
    type="continuous">
    <origin
      xyz="-0.0006 0.098703 -0.068248"
      rpy="0 0 0" />
    <parent
      link="leg_left" />
    <child
      link="leg2_left" />
    <axis
      xyz="-1 0 0" />
    <dynamics
      damping="0.0"
      friction="0.0" />
  </joint>
  <link
    name="leg3_left">
    <inertial>
      <origin
        xyz="-0.0240177949022405 -0.00952681182363596 -0.0183477774983369"
        rpy="0 0 0" />
      <mass
        value="0.177450614870689" />
      <inertia
        ixx="0.000125001022397629"
        ixy="1.93552642868024E-07"
        ixz="2.77490556714786E-07"
        iyy="0.000127562548065075"
        iyz="-1.29579673929925E-05"
        izz="1.38118491262305E-05" />
    </inertial>
    <visual>
      <origin
        xyz="0 0 0"
        rpy="0 0 0" />
      <geometry>
        <mesh
          filename="package://dancer_urdf_model/meshes/leg3_left.STL" />
      </geometry>
      <material
        name="">
        <color
          rgba="0.752941176470588 0.752941176470588 0.752941176470588 1" />
      </material>
    </visual>
    <collision>
      <origin
        xyz="0 0 0"
        rpy="0 0 0" />
      <geometry>
        <mesh
          filename="package://dancer_urdf_model/meshes/leg3_left.STL" />
      </geometry>
    </collision>
  </link>
  <joint
    name="joint_leg3_left"
    type="continuous">
    <origin
      xyz="0.0006 0.11852 0.05341"
      rpy="0 0 0" />
    <parent
      link="leg2_left" />
    <child
      link="leg3_left" />
    <axis
      xyz="-1 0 0" />
    <dynamics
      damping="0.0"
      friction="0.0" />
  </joint>
  <link
    name="leg4_left">
    <inertial>
      <origin
        xyz="0.00686471247682141 -0.0384681270411728 0.0369568564087829"
        rpy="0 0 0" />
      <mass
        value="0.13465253780049" />
      <inertia
        ixx="0.000175278373031919"
        ixy="-2.54500802762497E-06"
        ixz="-1.92782216931443E-06"
        iyy="0.00022389365941899"
        iyz="3.30376832465257E-06"
        izz="6.63305590940042E-05" />
    </inertial>
    <visual>
      <origin
        xyz="0 0 0"
        rpy="0 0 0" />
      <geometry>
        <mesh
          filename="package://dancer_urdf_model/meshes/leg4_left.STL" />
      </geometry>
      <material
        name="">
        <color
          rgba="0.866666666666667 0.909803921568627 1 1" />
      </material>
    </visual>
    <collision>
      <origin
        xyz="0 0 0"
        rpy="0 0 0" />
      <geometry>
        <mesh
          filename="package://dancer_urdf_model/meshes/leg4_left.STL" />
      </geometry>
    </collision>
  </link>
  <joint
    name="joint_leg4_left"
    type="continuous">
    <origin
      xyz="-0.0241 -0.0065502 0.035907"
      rpy="-2.9765 -0.0732 0.41369" />
    <parent
      link="leg3_left" />
    <child
      link="leg4_left" />
    <axis
      xyz="0 0 1" />
    <dynamics
      damping="0.0"
      friction="0.0" />
  </joint>
  <link
    name="body_hip_right">
    <inertial>
      <origin
        xyz="0.00360506662341747 0.00176962459685462 0.0179275732564661"
        rpy="0 0 0" />
      <mass
        value="0.0513468076618724" />
      <inertia
        ixx="5.31161382984344E-06"
        ixy="1.28428405213891E-08"
        ixz="8.92145319107081E-07"
        iyy="5.33310731202415E-06"
        iyz="4.39423590928376E-07"
        izz="5.5388043653725E-07" />
    </inertial>
    <visual>
      <origin
        xyz="0 0 0"
        rpy="0 0 0" />
      <geometry>
        <mesh
          filename="package://dancer_urdf_model/meshes/body_hip_right.STL" />
      </geometry>
      <material
        name="">
        <color
          rgba="1 1 1 1" />
      </material>
    </visual>
    <collision>
      <origin
        xyz="0 0 0"
        rpy="0 0 0" />
      <geometry>
        <mesh
          filename="package://dancer_urdf_model/meshes/body_hip_right.STL" />
      </geometry>
    </collision>
  </link>
  <joint
    name="joint_body_hip_right"
    type="continuous">
    <origin
      xyz="-0.045 -0.015 0.065"
      rpy="1.5708 -1.0684 0" />
    <parent
      link="body_hip" />
    <child
      link="body_hip_right" />
    <axis
      xyz="0 0 1" />
    <dynamics
      damping="0.0"
      friction="0.0" />
  </joint>
  <link
    name="body_hip2_right">
    <inertial>
      <origin
        xyz="-0.05274771645541 -0.00922434933235092 0.00864247622548692"
        rpy="0 0 0" />
      <mass
        value="0.178226118022815" />
      <inertia
        ixx="1.31914879715377E-05"
        ixy="8.31106180167271E-06"
        ixz="-7.32576193940501E-06"
        iyy="0.000144456519354766"
        iyz="1.87090627339956E-06"
        izz="0.000144645044815494" />
    </inertial>
    <visual>
      <origin
        xyz="0 0 0"
        rpy="0 0 0" />
      <geometry>
        <mesh
          filename="package://dancer_urdf_model/meshes/body_hip2_right.STL" />
      </geometry>
      <material
        name="">
        <color
          rgba="0.752941176470588 0.752941176470588 0.752941176470588 1" />
      </material>
    </visual>
    <collision>
      <origin
        xyz="0 0 0"
        rpy="0 0 0" />
      <geometry>
        <mesh
          filename="package://dancer_urdf_model/meshes/body_hip2_right.STL" />
      </geometry>
    </collision>
  </link>
  <joint
    name="joint_body_hip2_right"
    type="continuous">
    <origin
      xyz="0.031042 0.015283 0.0465"
      rpy="1.479 0 0.4575" />
    <parent
      link="body_hip_right" />
    <child
      link="body_hip2_right" />
    <axis
      xyz="-1 0 0" />
    <dynamics
      damping="0.0"
      friction="0.0" />
  </joint>
  <link
    name="leg_right">
    <inertial>
      <origin
        xyz="-0.0282237184526358 -0.0161687157017971 -0.0868287422428667"
        rpy="0 0 0" />
      <mass
        value="0.117898502766572" />
      <inertia
        ixx="8.19637542489574E-05"
        ixy="7.03755713098893E-08"
        ixz="5.13184590718679E-07"
        iyy="0.000107449613122845"
        iyz="8.61440649609276E-06"
        izz="2.73340514340446E-05" />
    </inertial>
    <visual>
      <origin
        xyz="0 0 0"
        rpy="0 0 0" />
      <geometry>
        <mesh
          filename="package://dancer_urdf_model/meshes/leg_right.STL" />
      </geometry>
      <material
        name="">
        <color
          rgba="0.752941176470588 0.752941176470588 0.752941176470588 1" />
      </material>
    </visual>
    <collision>
      <origin
        xyz="0 0 0"
        rpy="0 0 0" />
      <geometry>
        <mesh
          filename="package://dancer_urdf_model/meshes/leg_right.STL" />
      </geometry>
    </collision>
  </link>
  <joint
    name="joint_leg_right"
    type="continuous">
    <origin
      xyz="-0.0346 -0.019079 -0.02063"
      rpy="-0.34551 0.82443 -1.5708" />
    <parent
      link="body_hip2_right" />
    <child
      link="leg_right" />
    <axis
      xyz="1 0 0" />
    <dynamics
      damping="0.0"
      friction="0.0" />
  </joint>
  <link
    name="leg2_right">
    <inertial>
      <origin
        xyz="-0.0264999999999997 -0.0557112176708658 -0.0279922992874042"
        rpy="0 0 0" />
      <mass
        value="0.0278306854029525" />
      <inertia
        ixx="2.00646228342255E-06"
        ixy="5.43874561476066E-19"
        ixz="3.11390487234362E-19"
        iyy="1.58713263120878E-05"
        iyz="9.54567899565275E-07"
        izz="1.52540003080386E-05" />
    </inertial>
    <visual>
      <origin
        xyz="0 0 0"
        rpy="0 0 0" />
      <geometry>
        <mesh
          filename="package://dancer_urdf_model/meshes/leg2_right.STL" />
      </geometry>
      <material
        name="">
        <color
          rgba="0.752941176470588 0.752941176470588 0.752941176470588 1" />
      </material>
    </visual>
    <collision>
      <origin
        xyz="0 0 0"
        rpy="0 0 0" />
      <geometry>
        <mesh
          filename="package://dancer_urdf_model/meshes/leg2_right.STL" />
      </geometry>
    </collision>
  </link>
  <joint
    name="joint_leg2_right"
    type="continuous">
    <origin
      xyz="-0.0016 -0.020351 -0.11826"
      rpy="0 0 0" />
    <parent
      link="leg_right" />
    <child
      link="leg2_right" />
    <axis
      xyz="1 0 0" />
    <dynamics
      damping="0.0"
      friction="0.0" />
  </joint>
  <link
    name="leg3_right">
    <inertial>
      <origin
        xyz="-0.0265822088686737 0.0182514148314177 0.00971017334244767"
        rpy="0 0 0" />
      <mass
        value="0.177450615338578" />
      <inertia
        ixx="0.000125000929585061"
        ixy="2.75508514762772E-07"
        ixz="1.96364799986357E-07"
        iyy="1.35635016495756E-05"
        iyz="-1.18157178553736E-05"
        izz="0.000127810804117428" />
    </inertial>
    <visual>
      <origin
        xyz="0 0 0"
        rpy="0 0 0" />
      <geometry>
        <mesh
          filename="package://dancer_urdf_model/meshes/leg3_right.STL" />
      </geometry>
      <material
        name="">
        <color
          rgba="0.882352941176471 0.913725490196078 0.964705882352941 1" />
      </material>
    </visual>
    <collision>
      <origin
        xyz="0 0 0"
        rpy="0 0 0" />
      <geometry>
        <mesh
          filename="package://dancer_urdf_model/meshes/leg3_right.STL" />
      </geometry>
    </collision>
  </link>
  <joint
    name="joint_leg3_right"
    type="continuous">
    <origin
      xyz="0 -0.1146 -0.061382"
      rpy="0 0 0" />
    <parent
      link="leg2_right" />
    <child
      link="leg3_right" />
    <axis
      xyz="1 0 0" />
    <dynamics
      damping="0.0"
      friction="0.0" />
  </joint>
  <link
    name="leg4_right">
    <inertial>
      <origin
        xyz="0.0069030606371967 -0.0385611288608892 0.0368864105375638"
        rpy="0 0 0" />
      <mass
        value="0.133904507779755" />
      <inertia
        ixx="0.0001732330811679"
        ixy="-2.45904194210046E-06"
        ixz="-1.86270409287037E-06"
        iyy="0.000222022543722331"
        iyz="3.10162755525428E-06"
        izz="6.60854883669796E-05" />
    </inertial>
    <visual>
      <origin
        xyz="0 0 0"
        rpy="0 0 0" />
      <geometry>
        <mesh
          filename="package://dancer_urdf_model/meshes/leg4_right.STL" />
      </geometry>
      <material
        name="">
        <color
          rgba="0.898039215686275 0.917647058823529 0.929411764705882 1" />
      </material>
    </visual>
    <collision>
      <origin
        xyz="0 0 0"
        rpy="0 0 0" />
      <geometry>
        <mesh
          filename="package://dancer_urdf_model/meshes/leg4_right.STL" />
      </geometry>
    </collision>
  </link>
  <joint
    name="joint_leg4_right"
    type="continuous">
    <origin
      xyz="-0.0265 -0.035971 0.0061902"
      rpy="1.883 -0.9859 2.8787" />
    <parent
      link="leg3_right" />
    <child
      link="leg4_right" />
    <axis
      xyz="0 0 1" />
    <dynamics
      damping="0.0"
      friction="0.0" />
  </joint>
<!-- camera -->
  <link
    name="body_camera">
    <inertial>
      <origin
        xyz="-0.000405776775139921 -0.0107849933603513 0.0157740430047439"
        rpy="0 -1.5708 0" />
      <mass
        value="0.00912844677087833" />
      <inertia
        ixx="0"
        ixy="0"
        ixz="0"
        iyy="0"
        iyz="0"
        izz="0" />
    </inertial>
    <visual>
      <origin
        xyz="-0.000405776775139921 -0.0107849933603513 0.0157740430047439"
        rpy="0 -1.5708 0" />
      <geometry>
        <mesh
          filename="package://dancer_urdf_model/meshes/body_camera.STL" />
      </geometry>
      <material
        name="">
        <color
          rgba="1 1 1 1" />
      </material>
    </visual>
    <collision>
      <origin
        xyz="-0.000405776775139921 -0.0107849933603513 0.0157740430047439"
        rpy="0 -1.5708 0" />
      <geometry>
        <mesh
          filename="package://dancer_urdf_model/meshes/body_camera.STL" />
      </geometry>
    </collision>
  </link>
  <joint
    name="joint_body_camera"
    type="fixed">
    <origin
      xyz="-0.02015 -0.019786 -0.040504"
      rpy="1.1437 0 0" />
    <parent
      link="body_head2" />
    <child
      link="body_camera" />
    <axis
      xyz="-1 0 0" />
    <dynamics
      damping="0.0"
      friction="0.0" />
  </joint>
<!-- gazebo -->
  <gazebo reference="body_chest">
    <mu1>0.2</mu1>
    <mu2>0.2</mu2>
    <material>Gazebo/Gray</material>
  </gazebo>
  <gazebo reference="body_head">
    <mu1>0.2</mu1>
    <mu2>0.2</mu2>
    <material>Gazebo/Green</material>
  </gazebo>
  <gazebo reference="body_head2">
    <mu1>0.2</mu1>
    <mu2>0.2</mu2>
    <material>Gazebo/Green</material>
  </gazebo>
  <gazebo reference="arm_left">
    <mu1>0.2</mu1>
    <mu2>0.2</mu2>
    <material>Gazebo/Orange</material>
  </gazebo>
  <gazebo reference="hand_left">
    <mu1>0.2</mu1>
    <mu2>0.2</mu2>
    <material>Gazebo/Orange</material>
  </gazebo>
  <gazebo reference="arm_right">
    <mu1>0.2</mu1>
    <mu2>0.2</mu2>
    <material>Gazebo/Orange</material>
  </gazebo>
  <gazebo reference="hand_right">
    <mu1>0.2</mu1>
    <mu2>0.2</mu2>
    <material>Gazebo/Orange</material>
  </gazebo>
  <gazebo reference="body_hip">
    <mu1>0.2</mu1>
    <mu2>0.2</mu2>
    <material>Gazebo/Green</material>
  </gazebo>
  <gazebo reference="body_hip_left">
    <mu1>0.2</mu1>
    <mu2>0.2</mu2>
    <material>Gazebo/Black</material>
  </gazebo>
  <gazebo reference="body_hip2_left">
    <mu1>0.2</mu1>
    <mu2>0.2</mu2>
    <material>Gazebo/Black</material>
  </gazebo>
  <gazebo reference="leg_left">
    <mu1>0.2</mu1>
    <mu2>0.2</mu2>
    <material>Gazebo/Blue</material>
  </gazebo>
  <gazebo reference="leg2_left">
    <mu1>0.2</mu1>
    <mu2>0.2</mu2>
    <material>Gazebo/Blue</material>
  </gazebo>
  <gazebo reference="leg3_left">
    <mu1>0.2</mu1>
    <mu2>0.2</mu2>
    <material>Gazebo/Blue</material>
  </gazebo>
  <gazebo reference="leg4_left">
    <mu1>0.2</mu1>
    <mu2>0.2</mu2>
    <material>Gazebo/Blue</material>
  </gazebo>
  <gazebo reference="body_hip_right">
    <mu1>0.2</mu1>
    <mu2>0.2</mu2>
    <material>Gazebo/Black</material>
  </gazebo>
  <gazebo reference="body_hip2_right">
    <mu1>0.2</mu1>
    <mu2>0.2</mu2>
    <material>Gazebo/Black</material>
  </gazebo>
  <gazebo reference="leg_right">
    <mu1>0.2</mu1>
    <mu2>0.2</mu2>
    <material>Gazebo/Blue</material>
  </gazebo>
  <gazebo reference="leg2_right">
    <mu1>0.2</mu1>
    <mu2>0.2</mu2>
    <material>Gazebo/Blue</material>
  </gazebo>
  <gazebo reference="leg3_right">
    <mu1>0.2</mu1>
    <mu2>0.2</mu2>
     <material>Gazebo/Blue</material>
  </gazebo>
  <gazebo reference="leg4_right">
    <mu1>0.2</mu1>
    <mu2>0.2</mu2>
    <material>Gazebo/Blue</material>
  </gazebo>
  <gazebo reference="body_camera">
    <mu1>0.2</mu1>
    <mu2>0.2</mu2>
    <material>Gazebo/Red</material>
    <sensor type="camera" name="camera1">
      <always_on>1</always_on>
      <updateRate>30.0</updateRate>
      <visualize>true</visualize>
      <camera name="head">
        <horizontal_fov>1.3962634</horizontal_fov>
        <image>
          <width>800</width>
          <height>800</height>
          <format>R8G8B8</format>
        </image>
        <clip>
          <near>0.02</near>
          <far>300</far>
        </clip>
        <noise>
          <type>gaussian</type>
          <!-- Noise is sampled independently per pixel on each frame.
               That pixel's noise value is added to each of its color
               channels, which at that point lie in the range [0,1]. -->
          <mean>0.0</mean>
          <stddev>0.007</stddev>
        </noise>
      </camera>
      <plugin name="camera_controller" filename="libgazebo_ros_camera.so">
        <alwaysOn>true</alwaysOn>
        <updateRate>0.0</updateRate>
        <cameraName>dancer_urdf_model/camera</cameraName>
        <imageTopicName>image_raw</imageTopicName>
        <cameraInfoTopicName>camera_info</cameraInfoTopicName>
        <frameName>camera_link_optical</frameName>
        <hackBaseline>0.0</hackBaseline>
        <distortionK1>0.0</distortionK1>
        <distortionK2>0.0</distortionK2>
        <distortionK3>0.0</distortionK3>
        <distortionT1>0.0</distortionT1>
        <distortionT2>0.0</distortionT2>
        <CxPrime>0</CxPrime>
        <Cx>0.0</Cx>
        <Cy>0.0</Cy>
        <focalLength>0.0</focalLength>
      </plugin>
    </sensor>
  </gazebo>
<!-- transmission -->
  <gazebo>
    <plugin name="gazebo_ros_control" filename="libgazebo_ros_control.so">
      <robotNamespace>/dancer_urdf_model</robotNamespace>
      <robotSimType>gazebo_ros_control/DefaultRobotHWSim</robotSimType>
    </plugin>
  </gazebo>
  <transmission name="trans_body_head">
    <type>transmission_interface/SimpleTransmission</type>
    <joint name="joint_body_head">
      <hardwareInterface>hardware_interface/EffortJointInterface</hardwareInterface>
    </joint>
    <actuator name="motor_body_head">
      <mechanicalReduction>1</mechanicalReduction>
      <hardwareInterface>hardware_interface/EffortJointInterface</hardwareInterface>
    </actuator>
  </transmission>
  <transmission name="trans_body_head2">
    <type>transmission_interface/SimpleTransmission</type>
    <joint name="joint_body_head2">
      <hardwareInterface>hardware_interface/EffortJointInterface</hardwareInterface>
    </joint>
    <actuator name="motor_body_head2">
      <mechanicalReduction>1</mechanicalReduction>
      <hardwareInterface>hardware_interface/EffortJointInterface</hardwareInterface>
    </actuator>
  </transmission>
  <transmission name="trans_arm_left">
    <type>transmission_interface/SimpleTransmission</type>
    <joint name="joint_arm_left">
      <hardwareInterface>hardware_interface/EffortJointInterface</hardwareInterface>
    </joint>
    <actuator name="motor_arm_left">
      <mechanicalReduction>1</mechanicalReduction>
      <hardwareInterface>hardware_interface/EffortJointInterface</hardwareInterface>
    </actuator>
  </transmission>
  <transmission name="trans_hand_left">
    <type>transmission_interface/SimpleTransmission</type>
    <joint name="joint_hand_left">
      <hardwareInterface>hardware_interface/EffortJointInterface</hardwareInterface>
    </joint>
    <actuator name="motor_hand_left">
      <mechanicalReduction>1</mechanicalReduction>
      <hardwareInterface>hardware_interface/EffortJointInterface</hardwareInterface>
    </actuator>
  </transmission>
  <transmission name="trans_arm_right">
    <type>transmission_interface/SimpleTransmission</type>
    <joint name="joint_arm_right">
      <hardwareInterface>hardware_interface/EffortJointInterface</hardwareInterface>
    </joint>
    <actuator name="motor_arm_right">
      <mechanicalReduction>1</mechanicalReduction>
      <hardwareInterface>hardware_interface/EffortJointInterface</hardwareInterface>
    </actuator>
  </transmission>
  <transmission name="trans_hand_right">
    <type>transmission_interface/SimpleTransmission</type>
    <joint name="joint_hand_right">
      <hardwareInterface>hardware_interface/EffortJointInterface</hardwareInterface>
    </joint>
    <actuator name="motor_hand_right">
      <mechanicalReduction>1</mechanicalReduction>
      <hardwareInterface>hardware_interface/EffortJointInterface</hardwareInterface>
    </actuator>
  </transmission>
  <transmission name="trans_body_hip">
    <type>transmission_interface/SimpleTransmission</type>
    <joint name="joint_body_hip">
      <hardwareInterface>hardware_interface/EffortJointInterface</hardwareInterface>
    </joint>
    <actuator name="motor_body_hip">
      <mechanicalReduction>1</mechanicalReduction>
      <hardwareInterface>hardware_interface/EffortJointInterface</hardwareInterface>
    </actuator>
  </transmission>
  <transmission name="trans_body_hip_left">
    <type>transmission_interface/SimpleTransmission</type>
    <joint name="joint_body_hip_left">
      <hardwareInterface>hardware_interface/EffortJointInterface</hardwareInterface>
    </joint>
    <actuator name="motor_body_hip_left">
      <mechanicalReduction>1</mechanicalReduction>
      <hardwareInterface>hardware_interface/EffortJointInterface</hardwareInterface>
    </actuator>
  </transmission>
  <transmission name="trans_body_hip2_left">
    <type>transmission_interface/SimpleTransmission</type>
    <joint name="joint_body_hip2_left">
      <hardwareInterface>hardware_interface/EffortJointInterface</hardwareInterface>
    </joint>
    <actuator name="motor_body_hip2_left">
      <mechanicalReduction>1</mechanicalReduction>
      <hardwareInterface>hardware_interface/EffortJointInterface</hardwareInterface>
    </actuator>
  </transmission>
  <transmission name="trans_leg_left">
    <type>transmission_interface/SimpleTransmission</type>
    <joint name="joint_leg_left">
      <hardwareInterface>hardware_interface/EffortJointInterface</hardwareInterface>
    </joint>
    <actuator name="motor_leg_left">
      <mechanicalReduction>1</mechanicalReduction>
      <hardwareInterface>hardware_interface/EffortJointInterface</hardwareInterface>
    </actuator>
  </transmission>
  <transmission name="trans_leg2_left">
    <type>transmission_interface/SimpleTransmission</type>
    <joint name="joint_leg2_left">
      <hardwareInterface>hardware_interface/EffortJointInterface</hardwareInterface>
    </joint>
    <actuator name="motor_leg2_left">
      <mechanicalReduction>1</mechanicalReduction>
      <hardwareInterface>hardware_interface/EffortJointInterface</hardwareInterface>
    </actuator>
  </transmission>
  <transmission name="trans_leg3_left">
    <type>transmission_interface/SimpleTransmission</type>
    <joint name="joint_leg3_left">
      <hardwareInterface>hardware_interface/EffortJointInterface</hardwareInterface>
    </joint>
    <actuator name="motor_leg3_left">
      <mechanicalReduction>1</mechanicalReduction>
      <hardwareInterface>hardware_interface/EffortJointInterface</hardwareInterface>
    </actuator>
  </transmission>
  <transmission name="trans_leg4_left">
    <type>transmission_interface/SimpleTransmission</type>
    <joint name="joint_leg4_left">
      <hardwareInterface>hardware_interface/EffortJointInterface</hardwareInterface>
    </joint>
    <actuator name="motor_leg4_left">
      <mechanicalReduction>1</mechanicalReduction>
      <hardwareInterface>hardware_interface/EffortJointInterface</hardwareInterface>
    </actuator>
  </transmission>
  <transmission name="trans_body_hip_right">
    <type>transmission_interface/SimpleTransmission</type>
    <joint name="joint_body_hip_right">
      <hardwareInterface>hardware_interface/EffortJointInterface</hardwareInterface>
    </joint>
    <actuator name="motor_body_hip_right">
      <mechanicalReduction>1</mechanicalReduction>
      <hardwareInterface>hardware_interface/EffortJointInterface</hardwareInterface>
    </actuator>
  </transmission>
  <transmission name="trans_body_hip2_right">
    <type>transmission_interface/SimpleTransmission</type>
    <joint name="joint_body_hip2_right">
      <hardwareInterface>hardware_interface/EffortJointInterface</hardwareInterface>
    </joint>
    <actuator name="motor_body_hip2_right">
      <mechanicalReduction>1</mechanicalReduction>
      <hardwareInterface>hardware_interface/EffortJointInterface</hardwareInterface>
    </actuator>
  </transmission>
  <transmission name="trans_leg_right">
    <type>transmission_interface/SimpleTransmission</type>
    <joint name="joint_leg_right">
      <hardwareInterface>hardware_interface/EffortJointInterface</hardwareInterface>
    </joint>
    <actuator name="motor_leg_right">
      <mechanicalReduction>1</mechanicalReduction>
      <hardwareInterface>hardware_interface/EffortJointInterface</hardwareInterface>
    </actuator>
  </transmission>
  <transmission name="trans_leg2_right">
    <type>transmission_interface/SimpleTransmission</type>
    <joint name="joint_leg2_right">
      <hardwareInterface>hardware_interface/EffortJointInterface</hardwareInterface>
    </joint>
    <actuator name="motor_leg2_right">
      <mechanicalReduction>1</mechanicalReduction>
      <hardwareInterface>hardware_interface/EffortJointInterface</hardwareInterface>
    </actuator>
  </transmission>
  <transmission name="trans_leg3_right">
    <type>transmission_interface/SimpleTransmission</type>
    <joint name="joint_leg3_right">
      <hardwareInterface>hardware_interface/EffortJointInterface</hardwareInterface>
    </joint>
    <actuator name="motor_leg3_right">
      <mechanicalReduction>1</mechanicalReduction>
      <hardwareInterface>hardware_interface/EffortJointInterface</hardwareInterface>
    </actuator>
  </transmission>
  <transmission name="trans_leg4_right">
    <type>transmission_interface/SimpleTransmission</type>
    <joint name="joint_leg4_right">
      <hardwareInterface>hardware_interface/EffortJointInterface</hardwareInterface>
    </joint>
    <actuator name="motor_leg4_right">
      <mechanicalReduction>1</mechanicalReduction>
      <hardwareInterface>hardware_interface/EffortJointInterface</hardwareInterface>
    </actuator>
  </transmission>
</robot>
