<?xml version = "1.0"?>

<robot
  name="dancer_urdf_model" xmlns:xacro="http://www.ros.org/wiki/xacro">
  <!--关节阻尼与摩擦力-->
  <xacro:property name="dam" value="0.0"/>
  <xacro:property name="fri" value="0.0"/>
  <!--关节转动限制-->
  <xacro:property name="lim_effort" value="10000000.0"/>
  <xacro:property name="lim_vel" value="1.0"/>
  <!--上半身与下半身质量系数-->
  <xacro:property name="mass_upper" value="1.0"/><!--head,hip-->
  <xacro:property name="mass_hands" value="2.0"/><!--arm,hand-->
  <xacro:property name="mass_middle" value="4.0"/><!--hipleft,hipleft2,leg1-->
  <xacro:property name="mass_lower" value="10.0"/><!--leg2,leg3,leg4-->
  <!--gazebo摩擦力-->
  <xacro:property name="gazebo_mu1" value="0.4"/>
  <xacro:property name="gazebo_mu2" value="0.4"/>
<!-- root link -->
  <link 
    name="world_link">
  </link>
  <joint
    name="joint_world" type="fixed">
    <parent link="world_link"/>
    <child link="body_chest"/>
  </joint>
<!-- body -->
  <link
    name="body_chest">
    <inertial>
      <origin
        xyz="-0.39529 -0.25795 -0.0041722"
        rpy="0 0 0" />
      <mass
        value="${0.66907 * mass_upper}" />
      <inertia
        ixx="${0.001448202015 * sqrt(mass_upper)}"
        ixy="0"
        ixz="0"
        iyy="${0.000913481271 * sqrt(mass_upper)}"
        iyz="0"
        izz="${0.001648722294 * sqrt(mass_upper)}" />
    </inertial>
    <visual>
      <origin
        xyz="0 0 0"
        rpy="0 0 0" />
      <geometry>
        <mesh
          filename="package://dancer_urdf_model/meshes/body_chest.STL" />
      </geometry>
      <material
        name="">
        <color
          rgba="0.75294 0.75294 0.75294 1" />
      </material>
    </visual>
    <collision>
      <origin
        xyz="0 0 0"
        rpy="0 0 0" />
      <geometry>
        <mesh
          filename="package://dancer_urdf_model/meshes/body_chest.STL" />
      </geometry>
    </collision>
  </link>
  <link
    name="body_head">
    <inertial>
      <origin
        xyz="-0.000351851554432403 -0.0159432418124996 -6.20136945961303E-09"
        rpy="0 0 0" />
      <mass
        value="${0.05603 * mass_upper}" />
      <inertia
        ixx="${1.7946036e-05 * sqrt(mass_upper)}"
        ixy="0"
        ixz="0"
        iyy="${1.471574952e-05 * sqrt(mass_upper)}"
        iyz="0"
        izz="${1.471574952e-05 * sqrt(mass_upper)}" />
    </inertial>
    <visual>
      <origin
        xyz="0 0 0"
        rpy="0 0 0" />
      <geometry>
        <mesh
          filename="package://dancer_urdf_model/meshes/body_head.STL" />
      </geometry>
      <material
        name="">
        <color
          rgba="0.866666666666667 0.909803921568627 1 1" />
      </material>
    </visual>
    <collision>
      <origin
        xyz="0 0 0"
        rpy="0 0 0" />
      <geometry>
        <mesh
          filename="package://dancer_urdf_model/meshes/body_head.STL" />
      </geometry>
    </collision>
  </link>
  <joint
    name="joint_body_head"
    type="continuous">
    <origin
      xyz="-0.39482 -0.32209 -0.014452"
      rpy="2.6872 -0.050522 -3.1169" />
    <parent
      link="body_chest" />
    <child
      link="body_head" />
    <axis
      xyz="0 1 0" />
    <dynamics
      damping="${dam}"
      friction="${fri}" />
    <limit 
      effort="${lim_effort}" 
      velocity="${lim_vel}" />
  </joint>
  <link
    name="body_head2">
    <inertial>
      <origin
        xyz="-0.020399 -0.025987 -0.047171"
        rpy="0 0 0" />
      <mass
        value="${0.06736 * mass_upper}" />
      <inertia
        ixx="${2.4255387e-05 * mass_upper}"
        ixy="0"
        ixz="0"
        iyy="${3.3584382e-05 * mass_upper}"
        iyz="0"
        izz="${2.4255387e-05 * mass_upper}" />
    </inertial>
    <visual>
      <origin
        xyz="0 0 0"
        rpy="0 0 0" />
      <geometry>
        <mesh
          filename="package://dancer_urdf_model/meshes/body_head2.STL" />
      </geometry>
      <material
        name="">
        <color
          rgba="0.25098 0.25098 0.25098 1" />
      </material>
    </visual>
    <collision>
      <origin
        xyz="0 0 0"
        rpy="0 0 0" />
      <geometry>
        <mesh
          filename="package://dancer_urdf_model/meshes/body_head2.STL" />
      </geometry>
    </collision>
  </link>
  <joint
    name="joint_body_head2"
    type="continuous">
    <origin
      xyz="0.02015 -0.031182 0"
      rpy="-1.1164 0 0" />
    <parent
      link="body_head" />
    <child
      link="body_head2" />
    <axis
      xyz="-1 0 0" />
    <dynamics
      damping="${dam}"
      friction="${fri}" />
    <limit 
      effort="${lim_effort}" 
      velocity="${lim_vel}" />
  </joint>
  <link
    name="arm_left">
    <inertial>
      <origin
        xyz="0.00185814795587239 -0.0815728051955473 0.0294005743652034"
        rpy="0 0 0" />
      <mass
        value="${0.14297 * mass_hands}" />
      <inertia
        ixx="${0.000347545773 * sqrt(mass_hands)}"
        ixy="0"
        ixz="0"
        iyy="${8.5696218e-05 * sqrt(mass_hands)}"
        iyz="0"
        izz="${0.000347545773 * sqrt(mass_hands)}" />
    </inertial>
    <visual>
      <origin
        xyz="0 0 0"
        rpy="0 0 0" />
      <geometry>
        <mesh
          filename="package://dancer_urdf_model/meshes/arm_left.STL" />
      </geometry>
      <material
        name="">
        <color
          rgba="1 1 1 1" />
      </material>
    </visual>
    <collision>
      <origin
        xyz="0 0 0"
        rpy="0 0 0" />
      <geometry>
        <mesh
          filename="package://dancer_urdf_model/meshes/arm_left.STL" />
      </geometry>
    </collision>
  </link>
  <joint
    name="joint_arm_left"
    type="continuous">
    <origin
      xyz="-0.46902 -0.2921 0.00017561"
      rpy="-1.5708 1.09187 1.5708" /><!--rpy="-1.5708 -0.59813 1.5708" put 1.69 into p-->
    <parent
      link="body_chest" />
    <child
      link="arm_left" />
    <axis
      xyz="0 0 1" />
    <dynamics
      damping="${dam}"
      friction="${fri}" />
    <limit 
      effort="${lim_effort}" 
      velocity="${lim_vel}" />
  </joint>
  <link
    name="hand_left">
    <inertial>
      <origin
        xyz="-0.00150000000000006 0.0513998176588075 -0.0471166731147821"
        rpy="0 0 0" />
      <mass
        value="${0.02194 * mass_hands}" />
      <inertia
        ixx="${7.5982608e-05 * sqrt(mass_hands)}"
        ixy="0"
        ixz="0"
        iyy="${3.1050585e-06 * sqrt(mass_hands)}"
        iyz="0"
        izz="${7.32428505e-05 * sqrt(mass_hands)}" />
    </inertial>
    <visual>
      <origin
        xyz="0 0 0"
        rpy="0 0 0" />
      <geometry>
        <mesh
          filename="package://dancer_urdf_model/meshes/hand_left.STL" />
      </geometry>
      <material
        name="">
        <color
          rgba="1 1 1 1" />
      </material>
    </visual>
    <collision>
      <origin
        xyz="0 0 0"
        rpy="0 0 0" />
      <geometry>
        <mesh
          filename="package://dancer_urdf_model/meshes/hand_left.STL" />
      </geometry>
    </collision>
  </link>
  <joint
    name="joint_hand_left"
    type="continuous">
    <origin
      xyz="0 -0.136 0.05255"
      rpy="-2.36187 -1.5708 0" /><!--rpy="0.59813 -1.5708 0" put -2.96 into r-->
    <parent
      link="arm_left" />
    <child
      link="hand_left" />
    <axis
      xyz="1 0 0" />
    <dynamics
      damping="${dam}"
      friction="${fri}" />
    <limit 
      effort="${lim_effort}" 
      velocity="${lim_vel}" />
  </joint>
  <link
    name="arm_right">
    <inertial>
      <origin
        xyz="0.00187545595097149 -0.0810657497418857 0.0317817660201292"
        rpy="0 0 0" />
      <mass
        value="${0.14165 * mass_hands}" />
      <inertia
        ixx="${0.000347545773 * sqrt(mass_hands)}"
        ixy="0"
        ixz="0"
        iyy="${8.5696218e-05 * sqrt(mass_hands)}"
        iyz="0"
        izz="${0.000347545773 * sqrt(mass_hands)}" />
    </inertial>
    <visual>
      <origin
        xyz="0 0 0"
        rpy="0 0 0" />
      <geometry>
        <mesh
          filename="package://dancer_urdf_model/meshes/arm_right.STL" />
      </geometry>
      <material
        name="">
        <color
          rgba="0.898039215686275 0.917647058823529 0.929411764705882 1" />
      </material>
    </visual>
    <collision>
      <origin
        xyz="0 0 0"
        rpy="0 0 0" />
      <geometry>
        <mesh
          filename="package://dancer_urdf_model/meshes/arm_right.STL" />
      </geometry>
    </collision>
  </link>
  <joint
    name="joint_arm_right"
    type="continuous">
    <origin
      xyz="-0.25942 -0.2921 0.00017561"
      rpy="-1.5708 1.0973 1.5708" /><!--rpy="-1.5708 1.0373 1.5708" put 0.06 into p-->
    <parent
      link="body_chest" />
    <child
      link="arm_right" />
    <axis
      xyz="0 0 1" />
    <dynamics
      damping="${dam}"
      friction="${fri}" />
    <limit 
      effort="${lim_effort}" 
      velocity="${lim_vel}" />
  </joint>
  <link
    name="hand_right">
    <inertial>
      <origin
        xyz="-0.00150000000000061 -0.0550818675496146 -0.0427540642279834"
        rpy="0 0 0" />
      <mass
        value="${0.02194 * mass_hands}" />
      <inertia
        ixx="${7.5982608e-05 * sqrt(mass_hands)}"
        ixy="0"
        ixz="0"
        iyy="${3.1050585e-06 * sqrt(mass_hands)}"
        iyz="0"
        izz="${7.32428505e-05 * sqrt(mass_hands)}" />
    </inertial>
    <visual>
      <origin
        xyz="0 0 0"
        rpy="0 0 0" />
      <geometry>
        <mesh
          filename="package://dancer_urdf_model/meshes/hand_right.STL" />
      </geometry>
      <material
        name="">
        <color
          rgba="1 1 1 1" />
      </material>
    </visual>
    <collision>
      <origin
        xyz="0 0 0"
        rpy="0 0 0" />
      <geometry>
        <mesh
          filename="package://dancer_urdf_model/meshes/hand_right.STL" />
      </geometry>
    </collision>
  </link>
  <joint
    name="joint_hand_right"
    type="continuous">
    <origin
      xyz="0 -0.136 0.00845"
      rpy="-0.6557 1.5708 0" /><!--rpy="2.1043 1.5708 0" put -2.76 into r-->
    <parent
      link="arm_right" />
    <child
      link="hand_right" />
    <axis
      xyz="1 0 0" />
    <dynamics
      damping="${dam}"
      friction="${fri}" />
    <limit 
      effort="${lim_effort}" 
      velocity="${lim_vel}" />
  </joint>
  <link
    name="body_hip">
    <inertial>
      <origin
        xyz="0.000157245394557526 0.0183365350270815 0.0512514015755213"
        rpy="0 0 0" />
      <mass
        value="${0.22074 * mass_upper}" />
      <inertia
        ixx="${4.59415125e-05 * sqrt(mass_upper)}"
        ixy="0"
        ixz="0"
        iyy="${0.00014701284 * sqrt(mass_upper)}"
        iyz="0"
        izz="${0.0001341492165 * sqrt(mass_upper)}" />
    </inertial>
    <visual>
      <origin
        xyz="0 0 0"
        rpy="0 0 0" />
      <geometry>
        <mesh
          filename="package://dancer_urdf_model/meshes/body_hip.STL" />
      </geometry>
      <material
        name="">
        <color
          rgba="0.752941176470588 0.752941176470588 0.752941176470588 1" />
      </material>
    </visual>
    <collision>
      <origin
        xyz="0 0 0"
        rpy="0 0 0" />
      <geometry>
        <mesh
          filename="package://dancer_urdf_model/meshes/body_hip.STL" />
      </geometry>
    </collision>
  </link>
  <joint
    name="joint_body_hip"
    type="continuous">
    <origin
      xyz="-0.39482 -0.11668 0.01337"
      rpy="-0.45379 0 -3.1416" />
    <parent
      link="body_chest" />
    <child
      link="body_hip" />
    <axis
      xyz="0 1 0" />
    <dynamics
      damping="${dam}"
      friction="${fri}" />
    <limit 
      effort="${lim_effort}" 
      velocity="${lim_vel}" />
  </joint>
  <link
    name="body_hip_left">
    <inertial>
      <origin
        xyz="0.020727573256466 0.00401171130451616 -0.000185064805642399"
        rpy="0 0 0" />
      <mass
        value="${0.05134 * mass_middle}" />
      <inertia
        ixx="${3.419244e-05 * sqrt(mass_middle)}"
        ixy="0"
        ixz="0"
        iyy="${1.3676976e-05 * sqrt(mass_middle)}"
        iyz="0"
        izz="${3.419244e-05 * sqrt(mass_middle)}" />
    </inertial>
    <visual>
      <origin
        xyz="0 0 0"
        rpy="0 0 0" />
      <geometry>
        <mesh
          filename="package://dancer_urdf_model/meshes/body_hip_left.STL" />
      </geometry>
      <material
        name="">
        <color
          rgba="0.776470588235294 0.756862745098039 0.737254901960784 1" />
      </material>
    </visual>
    <collision>
      <origin
        xyz="0 0 0"
        rpy="0 0 0" />
      <geometry>
        <mesh
          filename="package://dancer_urdf_model/meshes/body_hip_left.STL" />
      </geometry>
    </collision>
  </link>
  <joint
    name="joint_body_hip_left"
    type="continuous">
    <origin
      xyz="0.045 -0.0122 0.065"
      rpy="1.6008 0 -1.5708" /><!--rpy="1.5708 0 -1.5708" put 0.03 into r-->
    <parent
      link="body_hip" />
    <child
      link="body_hip_left" />
    <axis
      xyz="-1 0 0" />
    <dynamics
      damping="${dam}"
      friction="${fri}" />
    <limit 
      effort="${lim_effort}" 
      velocity="${lim_vel}" />
  </joint>
  <link
    name="body_hip2_left">
    <inertial>
      <origin
        xyz="-0.05214771499803 -0.0126151296156827 0.000799339990500914"
        rpy="0 0 0" />
      <mass
        value="${0.17822 * mass_middle}" />
      <inertia
        ixx="${4.7477808e-05 * sqrt(mass_middle)}"
        ixy="0"
        ixz="0"
        iyy="${0.00011869452 * sqrt(mass_middle)}"
        iyz="0"
        izz="${0.00011869452 * sqrt(mass_middle)}" />
    </inertial>
    <visual>
      <origin
        xyz="0 0 0"
        rpy="0 0 0" />
      <geometry>
        <mesh
          filename="package://dancer_urdf_model/meshes/body_hip2_left.STL" />
      </geometry>
      <material
        name="">
        <color
          rgba="0.752941176470588 0.752941176470588 0.752941176470588 1" />
      </material>
    </visual>
    <collision>
      <origin
        xyz="0 0 0"
        rpy="0 0 0" />
      <geometry>
        <mesh
          filename="package://dancer_urdf_model/meshes/body_hip2_left.STL" />
      </geometry>
    </collision>
  </link>
  <joint
    name="joint_body_hip2_left"
    type="continuous">
    <origin
      xyz="0.0493 0.033966 -0.0015267"
      rpy="3.1698 0.044917 1.5708" /><!--rpy="3.0498 0.044917 1.5708" put -0.14 into -r-->
    <parent
      link="body_hip_left" /><!--put 0.12 into -r to leg ||-->
    <child
      link="body_hip2_left" />
    <axis
      xyz="-1 0 0" />
    <dynamics
      damping="${dam}"
      friction="${fri}" />
    <limit 
      effort="${lim_effort}" 
      velocity="${lim_vel}" />
  </joint>
  <link
    name="leg_left">
    <inertial>
      <origin
        xyz="-0.0239762815919513 0.0733271184441349 -0.0492320368464383"
        rpy="0 0 0" />
      <mass
        value="${0.11789 * mass_middle}" />
      <inertia
        ixx="${0.000427905333 * sqrt(mass_middle)}"
        ixy="0"
        ixz="0"
        iyy="${7.0663266e-05 * sqrt(mass_middle)}"
        iyz="0"
        izz="${0.000427905333 * sqrt(mass_middle)}" />
    </inertial>
    <visual>
      <origin
        xyz="0 0 0"
        rpy="0 0 0" />
      <geometry>
        <mesh
          filename="package://dancer_urdf_model/meshes/leg_left.STL" />
      </geometry>
      <material
        name="">
        <color
          rgba="0.752941176470588 0.752941176470588 0.752941176470588 1" />
      </material>
    </visual>
    <collision>
      <origin
        xyz="0 0 0"
        rpy="0 0 0" />
      <geometry>
        <mesh
          filename="package://dancer_urdf_model/meshes/leg_left.STL" />
      </geometry>
    </collision>
  </link>
  <joint
    name="joint_leg_left"
    type="continuous">
    <origin
      xyz="-0.034 0.0013682 0.024061"
      rpy="-1.0064 -1.514 1.5708" /><!--rpy="-2.6864 -1.514 1.5708" /> put -1.68 into r-->
    <parent
      link="body_hip2_left" />
    <child
      link="leg_left" />
    <axis
      xyz="-1 0 0" />
    <dynamics
      damping="${dam}"
      friction="${fri}" />
    <limit 
      effort="${lim_effort}" 
      velocity="${lim_vel}" />
  </joint>
  <link
    name="leg2_left">
    <inertial>
      <origin
        xyz="-0.0235000000000001 0.0561541813174893 0.0270927391440708"
        rpy="0 0 0" />
      <mass
        value="${0.02783 * mass_lower}" />
      <inertia
        ixx="${0.000101014551 * sqrt(mass_lower)}"
        ixy="0"
        ixz="0"
        iyy="${1.6681302e-05 * sqrt(mass_lower)}"
        iyz="0"
        izz="${0.000101014551 * sqrt(mass_lower)}" />
    </inertial>
    <visual>
      <origin
        xyz="0 0 0"
        rpy="0 0 0" />
      <geometry>
        <mesh
          filename="package://dancer_urdf_model/meshes/leg2_left.STL" />
      </geometry>
      <material
        name="">
        <color
          rgba="0.866666666666667 0.909803921568627 1 1" />
      </material>
    </visual>
    <collision>
      <origin
        xyz="0 0 0"
        rpy="0 0 0" />
      <geometry>
        <mesh
          filename="package://dancer_urdf_model/meshes/leg2_left.STL" />
      </geometry>
    </collision>
  </link>
  <joint
    name="joint_leg2_left"
    type="continuous">
    <origin
      xyz="-0.0006 0.098703 -0.068248"
      rpy="-1.05 0 0" /><!--rpy="0 0 0" put 1.05 into r-->
    <parent
      link="leg_left" />
    <child
      link="leg2_left" />
    <axis
      xyz="-1 0 0" />
    <dynamics
      damping="${dam}"
      friction="${fri}" />
    <limit 
      effort="${lim_effort}" 
      velocity="${lim_vel}" />
  </joint>
  <link
    name="leg3_left">
    <inertial>
      <origin
        xyz="-0.0240177949022405 -0.00952681182363596 -0.0183477774983369"
        rpy="0 0 0" />
      <mass
        value="${0.17745 * mass_lower}" />
      <inertia
        ixx="${0.0001181817 * sqrt(mass_lower)}"
        ixy="0"
        ixz="0"
        iyy="${0.000147727125 * sqrt(mass_lower)}"
        iyz="0"
        izz="${7.6818105e-05 * sqrt(mass_lower)}" />
    </inertial>
    <visual>
      <origin
        xyz="0 0 0"
        rpy="0 0 0" />
      <geometry>
        <mesh
          filename="package://dancer_urdf_model/meshes/leg3_left.STL" />
      </geometry>
      <material
        name="">
        <color
          rgba="0.752941176470588 0.752941176470588 0.752941176470588 1" />
      </material>
    </visual>
    <collision>
      <origin
        xyz="0 0 0"
        rpy="0 0 0" />
      <geometry>
        <mesh
          filename="package://dancer_urdf_model/meshes/leg3_left.STL" />
      </geometry>
    </collision>
  </link>
  <joint
    name="joint_leg3_left"
    type="continuous">
    <origin
      xyz="0.0006 0.11852 0.05341"
      rpy="0.41 0 0" /><!--rpy="0 0 0" put -0.19 into -r-->
    <parent
      link="leg2_left" /><!-- put -0.22 into -r to prevent falling-->
    <child
      link="leg3_left" />
    <axis
      xyz="-1 0 0" />
    <dynamics
      damping="${dam}"
      friction="${fri}" />
    <limit 
      effort="${lim_effort}" 
      velocity="${lim_vel}" />
  </joint>
  <link
    name="leg4_left">
    <inertial>
      <origin
        xyz="0.00686471247682141 -0.0384681270411728 0.0369568564087829"
        rpy="0 0 0" />
      <mass
        value="${0.13465 * mass_lower}" />
      <inertia
        ixx="${0.000919188225 * sqrt(mass_lower)}"
        ixy="0"
        ixz="0"
        iyy="${0.00132721812 * sqrt(mass_lower)}"
        iyz="0"
        izz="${0.000488739105 * sqrt(mass_lower)}" />
    </inertial>
    <visual>
      <origin
        xyz="0 0 0"
        rpy="0 0 0" />
      <geometry>
        <mesh
          filename="package://dancer_urdf_model/meshes/leg4_left.STL" />
      </geometry>
      <material
        name="">
        <color
          rgba="0.866666666666667 0.909803921568627 1 1" />
      </material>
    </visual>
    <collision>
      <origin
        xyz="0 0 0"
        rpy="0 0 0" />
      <geometry>
        <mesh
          filename="package://dancer_urdf_model/meshes/leg4_left.STL" />
      </geometry>
    </collision>
  </link>
  <joint
    name="joint_leg4_left"
    type="continuous">
    <origin
      xyz="-0.0241 -0.0065502 0.035907"
      rpy="-2.9765 -0.0132 0.03369" /><!--rpy="-2.9765 -0.0732 0.41369" put 0.41 into p-->
    <parent
      link="leg3_left" /><!-- and put -0.35 into p-->
    <child
      link="leg4_left" /><!-- and put -0.30 into y-->
    <axis
      xyz="0 0 1" /><!--put 0.08 into -y to leg ||-->
    <dynamics
      damping="${dam}"
      friction="${fri}" />
    <limit 
      effort="${lim_effort}" 
      velocity="${lim_vel}" />
  </joint>
  <link
    name="body_hip_right">
    <inertial>
      <origin
        xyz="0.00360506662341747 0.00176962459685462 0.0179275732564661"
        rpy="0 0 0" />
      <mass
        value="${0.05134 * mass_middle}" />
      <inertia
        ixx="${3.419244e-05 * sqrt(mass_middle)}"
        ixy="0"
        ixz="0"
        iyy="${1.3676976e-05 * sqrt(mass_middle)}"
        iyz="0"
        izz="${3.419244e-05 * sqrt(mass_middle)}" />
    </inertial>
    <visual>
      <origin
        xyz="0 0 0"
        rpy="0 0 0" />
      <geometry>
        <mesh
          filename="package://dancer_urdf_model/meshes/body_hip_right.STL" />
      </geometry>
      <material
        name="">
        <color
          rgba="1 1 1 1" />
      </material>
    </visual>
    <collision>
      <origin
        xyz="0 0 0"
        rpy="0 0 0" />
      <geometry>
        <mesh
          filename="package://dancer_urdf_model/meshes/body_hip_right.STL" />
      </geometry>
    </collision>
  </link>
  <joint
    name="joint_body_hip_right"
    type="continuous">
    <origin
      xyz="-0.045 -0.015 0.065"
      rpy="1.5708 -1.1184 0" /><!--rpy="1.5708 -1.0684 0" put 0.05 into p-->
    <parent
      link="body_hip" />
    <child
      link="body_hip_right" />
    <axis
      xyz="0 0 1" />
    <dynamics
      damping="${dam}"
      friction="${fri}" />
    <limit 
      effort="${lim_effort}" 
      velocity="${lim_vel}" />
  </joint>
  <link
    name="body_hip2_right">
    <inertial>
      <origin
        xyz="-0.05274771645541 -0.00922434933235092 0.00864247622548692"
        rpy="0 0 0" />
      <mass
        value="${0.17822 * mass_middle}" />
      <inertia
        ixx="${4.7477808e-05 * sqrt(mass_middle)}"
        ixy="0"
        ixz="0"
        iyy="${0.00011869452 * sqrt(mass_middle)}"
        iyz="0"
        izz="${0.00011869452 * sqrt(mass_middle)}" />
    </inertial>
    <visual>
      <origin
        xyz="0 0 0"
        rpy="0 0 0" />
      <geometry>
        <mesh
          filename="package://dancer_urdf_model/meshes/body_hip2_right.STL" />
      </geometry>
      <material
        name="">
        <color
          rgba="0.752941176470588 0.752941176470588 0.752941176470588 1" />
      </material>
    </visual>
    <collision>
      <origin
        xyz="0 0 0"
        rpy="0 0 0" />
      <geometry>
        <mesh
          filename="package://dancer_urdf_model/meshes/body_hip2_right.STL" />
      </geometry>
    </collision>
  </link>
  <joint
    name="joint_body_hip2_right"
    type="continuous">
    <origin
      xyz="0.031042 0.015283 0.0465"
      rpy="2.299 0 0.4575" /><!--rpy="1.479 0 0.4575" put -0.83 into -r-->
    <parent
      link="body_hip_right" /><!-- and put 0.08 into -r-->
    <child
      link="body_hip2_right" /><!--put -0.07 into -r to leg ||-->
    <axis
      xyz="-1 0 0" />
    <dynamics
      damping="${dam}"
      friction="${fri}" />
    <limit 
      effort="${lim_effort}" 
      velocity="${lim_vel}" />
  </joint>
  <link
    name="leg_right">
    <inertial>
      <origin
        xyz="-0.0282237184526358 -0.0161687157017971 -0.0868287422428667"
        rpy="0 0 0" />
      <mass
        value="${0.11789 * mass_middle}" />
      <inertia
        ixx="${0.000427905333 * sqrt(mass_middle)}"
        ixy="0"
        ixz="0"
        iyy="${0.000427905333 * sqrt(mass_middle)}"
        iyz="0"
        izz="${7.0663266e-05 * sqrt(mass_middle)}" />
    </inertial>
    <visual>
      <origin
        xyz="0 0 0"
        rpy="0 0 0" />
      <geometry>
        <mesh
          filename="package://dancer_urdf_model/meshes/leg_right.STL" />
      </geometry>
      <material
        name="">
        <color
          rgba="0.752941176470588 0.752941176470588 0.752941176470588 1" />
      </material>
    </visual>
    <collision>
      <origin
        xyz="0 0 0"
        rpy="0 0 0" />
      <geometry>
        <mesh
          filename="package://dancer_urdf_model/meshes/leg_right.STL" />
      </geometry>
    </collision>
  </link>
  <joint
    name="joint_leg_right"
    type="continuous">
    <origin
      xyz="-0.0346 -0.019079 -0.02063"
      rpy="0.20449 0.82443 -1.5708" /><!--rpy="-0.34551 0.82443 -1.5708" put 0.55 into r-->
    <parent
      link="body_hip2_right" />
    <child
      link="leg_right" />
    <axis
      xyz="1 0 0" />
    <dynamics
      damping="${dam}"
      friction="${fri}" />
    <limit 
      effort="${lim_effort}" 
      velocity="${lim_vel}" />
  </joint>
  <link
    name="leg2_right">
    <inertial>
      <origin
        xyz="-0.0264999999999997 -0.0557112176708658 -0.0279922992874042"
        rpy="0 0 0" />
      <mass
        value="${0.02783 * mass_lower}" />
      <inertia
        ixx="${0.000101014551 * sqrt(mass_lower)}"
        ixy="0"
        ixz="0"
        iyy="${1.6681302e-05 * sqrt(mass_lower)}"
        iyz="0"
        izz="${0.000101014551 * sqrt(mass_lower)}" />
    </inertial>
    <visual>
      <origin
        xyz="0 0 0"
        rpy="0 0 0" />
      <geometry>
        <mesh
          filename="package://dancer_urdf_model/meshes/leg2_right.STL" />
      </geometry>
      <material
        name="">
        <color
          rgba="0.752941176470588 0.752941176470588 0.752941176470588 1" />
      </material>
    </visual>
    <collision>
      <origin
        xyz="0 0 0"
        rpy="0 0 0" />
      <geometry>
        <mesh
          filename="package://dancer_urdf_model/meshes/leg2_right.STL" />
      </geometry>
    </collision>
  </link>
  <joint
    name="joint_leg2_right"
    type="continuous">
    <origin
      xyz="-0.0016 -0.020351 -0.11826"
      rpy="0.94 0 0" /><!--rpy="0 0 0" put 0.79 into r-->
    <parent
      link="leg_right" /><!-- and put 0.15 into r-->
    <child
      link="leg2_right" />
    <axis
      xyz="1 0 0" />
    <dynamics
      damping="${dam}"
      friction="${fri}" />
    <limit 
      effort="${lim_effort}" 
      velocity="${lim_vel}" />
  </joint>
  <link
    name="leg3_right">
    <inertial>
      <origin
        xyz="-0.0265822088686737 0.0182514148314177 0.00971017334244767"
        rpy="0 0 0" />
      <mass
        value="${0.17745 * mass_lower}" />
      <inertia
        ixx="${0.0001181817 * sqrt(mass_lower)}"
        ixy="0"
        ixz="0"
        iyy="${0.000147727125 * sqrt(mass_lower)}"
        iyz="0"
        izz="${7.6818105e-05 * sqrt(mass_lower)}" />
    </inertial>
    <visual>
      <origin
        xyz="0 0 0"
        rpy="0 0 0" />
      <geometry>
        <mesh
          filename="package://dancer_urdf_model/meshes/leg3_right.STL" />
      </geometry>
      <material
        name="">
        <color
          rgba="0.882352941176471 0.913725490196078 0.964705882352941 1" />
      </material>
    </visual>
    <collision>
      <origin
        xyz="0 0 0"
        rpy="0 0 0" />
      <geometry>
        <mesh
          filename="package://dancer_urdf_model/meshes/leg3_right.STL" />
      </geometry>
    </collision>
  </link>
  <joint
    name="joint_leg3_right"
    type="continuous">
    <origin
      xyz="0 -0.1146 -0.061382"
      rpy="-1.05 0 0" /><!--rpy="0 0 0" put -0.83 into r-->
    <parent
      link="leg2_right" /><!-- put -0.22 into r to prevent falling-->
    <child
      link="leg3_right" />
    <axis
      xyz="1 0 0" />
    <dynamics
      damping="${dam}"
      friction="${fri}" />
    <limit 
      effort="${lim_effort}" 
      velocity="${lim_vel}" />
  </joint>
  <link
    name="leg4_right">
    <inertial>
      <origin
        xyz="0.0069030606371967 -0.0385611288608892 0.0368864105375638"
        rpy="0 0 0" />
      <mass
        value="${0.13390 * mass_lower}" />
      <inertia
        ixx="${0.000919188225 * sqrt(mass_lower)}"
        ixy="0"
        ixz="0"
        iyy="${0.00132721812 * sqrt(mass_lower)}"
        iyz="0"
        izz="${0.000488739105 * sqrt(mass_lower)}" />
    </inertial>
    <visual>
      <origin
        xyz="0 0 0"
        rpy="0 0 0" />
      <geometry>
        <mesh
          filename="package://dancer_urdf_model/meshes/leg4_right.STL" />
      </geometry>
      <material
        name="">
        <color
          rgba="0.898039215686275 0.917647058823529 0.929411764705882 1" />
      </material>
    </visual>
    <collision>
      <origin
        xyz="0 0 0"
        rpy="0 0 0" />
      <geometry>
        <mesh
          filename="package://dancer_urdf_model/meshes/leg4_right.STL" />
      </geometry>
    </collision>
  </link>
  <joint
    name="joint_leg4_right"
    type="continuous">
    <origin
      xyz="-0.0265 -0.035971 0.0061902"
      rpy="1.753 0.0141 3.1487" /><!--rpy="1.883 -0.9859 2.8787" put -1.08 into p-->
    <parent
      link="leg3_right" /><!-- and put 0.27 into y-->
    <child
      link="leg4_right" /><!-- and put -0.13 into r-->
    <axis
      xyz="0 0 1" /><!-- and put -0.20 into p-->
    <dynamics
      damping="${dam}"
      friction="${fri}" /><!--put -0.12 into -p to leg ||-->
    <limit 
      effort="${lim_effort}" 
      velocity="${lim_vel}" />
  </joint>
<!-- camera -->
  <link
    name="body_camera">
    <inertial>
      <origin
        xyz="-0.000405776775139921 -0.0107849933603513 0.0157740430047439"
        rpy="0 -1.5708 0" />
      <mass
        value="${0.00912 * mass_upper}" />
      <inertia
        ixx="0"
        ixy="0"
        ixz="0"
        iyy="0"
        iyz="0"
        izz="0" />
    </inertial>
    <visual>
      <origin
        xyz="-0.000405776775139921 -0.0107849933603513 0.0157740430047439"
        rpy="0 -1.5708 0" />
      <geometry>
        <mesh
          filename="package://dancer_urdf_model/meshes/body_camera.STL" />
      </geometry>
      <material
        name="">
        <color
          rgba="1 1 1 1" />
      </material>
    </visual>
    <collision>
      <origin
        xyz="-0.000405776775139921 -0.0107849933603513 0.0157740430047439"
        rpy="0 -1.5708 0" />
      <geometry>
        <mesh
          filename="package://dancer_urdf_model/meshes/body_camera.STL" />
      </geometry>
    </collision>
  </link>
  <joint
    name="joint_body_camera"
    type="fixed">
    <origin
      xyz="-0.02015 -0.019786 -0.040504"
      rpy="1.1437 0 -1.5779" />
    <parent
      link="body_head2" />
    <child
      link="body_camera" />
    <axis
      xyz="-1 0 0" />
  </joint>
  <!--rpy="1.1437 0 -1.5779"-->
<!-- gazebo -->
  <gazebo reference="body_chest">
    <mu1>${gazebo_mu1}</mu1>
    <mu2>${gazebo_mu2}</mu2>
    <material>Gazebo/Gray</material>
    <gravity>true</gravity>
    <!--<turnGravityoff>false</turnGravityoff>-->
  </gazebo>
  <gazebo reference="body_head">
    <mu1>${gazebo_mu1}</mu1>
    <mu2>${gazebo_mu2}</mu2>
    <material>Gazebo/Green</material>
    <gravity>true</gravity>
    <!--<turnGravityoff>false</turnGravityoff>-->
  </gazebo>
  <gazebo reference="body_head2">
    <mu1>${gazebo_mu1}</mu1>
    <mu2>${gazebo_mu2}</mu2>
    <material>Gazebo/Yellow</material>
    <gravity>true</gravity>
    <!--<turnGravityoff>false</turnGravityoff>-->
  </gazebo>
  <gazebo reference="arm_left">
    <mu1>${gazebo_mu1}</mu1>
    <mu2>${gazebo_mu2}</mu2>
    <material>Gazebo/Orange</material>
    <gravity>true</gravity>
    <!--<turnGravityoff>false</turnGravityoff>-->
  </gazebo>
  <gazebo reference="hand_left">
    <mu1>${gazebo_mu1}</mu1>
    <mu2>${gazebo_mu2}</mu2>
    <material>Gazebo/Yellow</material>
    <gravity>true</gravity>
    <!--<turnGravityoff>false</turnGravityoff>-->
  </gazebo>
  <gazebo reference="arm_right">
    <mu1>${gazebo_mu1}</mu1>
    <mu2>${gazebo_mu2}</mu2>
    <material>Gazebo/Black</material>
    <gravity>true</gravity>
    <!--<turnGravityoff>false</turnGravityoff>-->
  </gazebo>
  <gazebo reference="hand_right">
    <mu1>${gazebo_mu1}</mu1>
    <mu2>${gazebo_mu2}</mu2>
    <material>Gazebo/Black</material>
    <gravity>true</gravity>
    <!--<turnGravityoff>false</turnGravityoff>-->
  </gazebo>
  <gazebo reference="body_hip">
    <mu1>${gazebo_mu1}</mu1>
    <mu2>${gazebo_mu2}</mu2>
    <material>Gazebo/Green</material>
    <gravity>true</gravity>
    <!--<turnGravityoff>false</turnGravityoff>-->
  </gazebo>
  <gazebo reference="body_hip_left">
    <mu1>${gazebo_mu1}</mu1>
    <mu2>${gazebo_mu2}</mu2>
    <material>Gazebo/Yellow</material>
    <gravity>true</gravity>
    <!--<turnGravityoff>false</turnGravityoff>-->
  </gazebo>
  <gazebo reference="body_hip2_left">
    <mu1>${gazebo_mu1}</mu1>
    <mu2>${gazebo_mu2}</mu2>
    <material>Gazebo/Orange</material>
    <gravity>true</gravity>
    <!--<turnGravityoff>false</turnGravityoff>-->
  </gazebo>
  <gazebo reference="leg_left">
    <mu1>${gazebo_mu1}</mu1>
    <mu2>${gazebo_mu2}</mu2>
    <material>Gazebo/Yellow</material>
    <gravity>true</gravity>
    <!--<turnGravityoff>false</turnGravityoff>-->
  </gazebo>
  <gazebo reference="leg2_left">
    <mu1>${gazebo_mu1}</mu1>
    <mu2>${gazebo_mu2}</mu2>
    <material>Gazebo/Orange</material>
    <gravity>true</gravity>
    <!--<turnGravityoff>false</turnGravityoff>-->
  </gazebo>
  <gazebo reference="leg3_left">
    <mu1>${gazebo_mu1}</mu1>
    <mu2>${gazebo_mu2}</mu2>
    <material>Gazebo/Yellow</material>
    <gravity>true</gravity>
    <!--<turnGravityoff>false</turnGravityoff>-->
  </gazebo>
  <gazebo reference="leg4_left">
    <mu1>${gazebo_mu1}</mu1>
    <mu2>${gazebo_mu2}</mu2>
    <material>Gazebo/Orange</material>
    <gravity>true</gravity>
    <!--<turnGravityoff>false</turnGravityoff>-->
  </gazebo>
  <gazebo reference="body_hip_right">
    <mu1>${gazebo_mu1}</mu1>
    <mu2>${gazebo_mu2}</mu2>
    <material>Gazebo/Yellow</material>
    <gravity>true</gravity>
    <!--<turnGravityoff>false</turnGravityoff>-->
  </gazebo>
  <gazebo reference="body_hip2_right">
    <mu1>${gazebo_mu1}</mu1>
    <mu2>${gazebo_mu2}</mu2>
    <material>Gazebo/Orange</material>
    <gravity>true</gravity>
    <!--<turnGravityoff>false</turnGravityoff>-->
  </gazebo>
  <gazebo reference="leg_right">
    <mu1>${gazebo_mu1}</mu1>
    <mu2>${gazebo_mu2}</mu2>
    <material>Gazebo/Black</material>
    <gravity>true</gravity>
    <!--<turnGravityoff>false</turnGravityoff>-->
  </gazebo>
  <gazebo reference="leg2_right">
    <mu1>${gazebo_mu1}</mu1>
    <mu2>${gazebo_mu2}</mu2>
    <material>Gazebo/Black</material>
    <gravity>true</gravity>
    <!--<turnGravityoff>false</turnGravityoff>-->
  </gazebo>
  <gazebo reference="leg3_right">
    <mu1>${gazebo_mu1}</mu1>
    <mu2>${gazebo_mu2}</mu2>
     <material>Gazebo/Black</material>
    <gravity>true</gravity>
    <!--<turnGravityoff>false</turnGravityoff>-->
  </gazebo>
  <gazebo reference="leg4_right">
    <mu1>${gazebo_mu1}</mu1>
    <mu2>${gazebo_mu2}</mu2>
    <material>Gazebo/Black</material>
    <gravity>true</gravity>
    <!--<turnGravityoff>false</turnGravityoff>-->
  </gazebo>
  <gazebo reference="body_camera">
    <mu1>${gazebo_mu1}</mu1>
    <mu2>${gazebo_mu2}</mu2>
    <material>Gazebo/Red</material>
    <sensor type="camera" name="camera1">
      <always_on>true</always_on>
      <!--<updateRate>30.0</updateRate>-->
      <visualize>false</visualize>
      <camera name="head">
        <horizontal_fov>1.3962634</horizontal_fov>
        <image>
          <width>800</width>
          <height>800</height>
          <format>R8G8B8</format>
        </image>
        <clip>
          <near>0.02</near>
          <far>300</far>
        </clip>
        <noise>
          <type>gaussian</type>
          <!-- Noise is sampled independently per pixel on each frame.
               That pixel's noise value is added to each of its color
               channels, which at that point lie in the range [0,1]. -->
          <mean>0.0</mean>
          <stddev>0.007</stddev>
        </noise>
      </camera>
      <plugin name="camera_controller" filename="libgazebo_ros_camera.so">
        <alwaysOn>true</alwaysOn>
        <!--<updateRate>0.0</updateRate>-->
        <cameraName>dancer_urdf_model/camera</cameraName>
        <imageTopicName>image_raw</imageTopicName>
        <cameraInfoTopicName>camera_info</cameraInfoTopicName>
        <frameName>camera_link_optical</frameName>
        <hackBaseline>0.0</hackBaseline>
        <distortionK1>0.0</distortionK1>
        <distortionK2>0.0</distortionK2>
        <distortionK3>0.0</distortionK3>
        <distortionT1>0.0</distortionT1>
        <distortionT2>0.0</distortionT2>
        <CxPrime>0</CxPrime>
        <Cx>0.0</Cx>
        <Cy>0.0</Cy>
        <focalLength>0.0</focalLength>
      </plugin>
    </sensor>
  </gazebo>
<!-- transmission -->
  <transmission name="trans_body_head">
    <type>transmission_interface/SimpleTransmission</type>
    <joint name="joint_body_head">
      <hardwareInterface>hardware_interface/EffortJointInterface</hardwareInterface>
    </joint>
    <actuator name="motor_body_head">
      <mechanicalReduction>1</mechanicalReduction>
      <hardwareInterface>hardware_interface/EffortJointInterface</hardwareInterface>
    </actuator>
  </transmission>
  <transmission name="trans_body_head2">
    <type>transmission_interface/SimpleTransmission</type>
    <joint name="joint_body_head2">
      <hardwareInterface>hardware_interface/EffortJointInterface</hardwareInterface>
    </joint>
    <actuator name="motor_body_head2">
      <mechanicalReduction>1</mechanicalReduction>
      <hardwareInterface>hardware_interface/EffortJointInterface</hardwareInterface>
    </actuator>
  </transmission>
  <transmission name="trans_arm_left">
    <type>transmission_interface/SimpleTransmission</type>
    <joint name="joint_arm_left">
      <hardwareInterface>hardware_interface/EffortJointInterface</hardwareInterface>
    </joint>
    <actuator name="motor_arm_left">
      <mechanicalReduction>1</mechanicalReduction>
      <hardwareInterface>hardware_interface/EffortJointInterface</hardwareInterface>
    </actuator>
  </transmission>
  <transmission name="trans_hand_left">
    <type>transmission_interface/SimpleTransmission</type>
    <joint name="joint_hand_left">
      <hardwareInterface>hardware_interface/EffortJointInterface</hardwareInterface>
    </joint>
    <actuator name="motor_hand_left">
      <mechanicalReduction>1</mechanicalReduction>
      <hardwareInterface>hardware_interface/EffortJointInterface</hardwareInterface>
    </actuator>
  </transmission>
  <transmission name="trans_arm_right">
    <type>transmission_interface/SimpleTransmission</type>
    <joint name="joint_arm_right">
      <hardwareInterface>hardware_interface/EffortJointInterface</hardwareInterface>
    </joint>
    <actuator name="motor_arm_right">
      <mechanicalReduction>1</mechanicalReduction>
      <hardwareInterface>hardware_interface/EffortJointInterface</hardwareInterface>
    </actuator>
  </transmission>
  <transmission name="trans_hand_right">
    <type>transmission_interface/SimpleTransmission</type>
    <joint name="joint_hand_right">
      <hardwareInterface>hardware_interface/EffortJointInterface</hardwareInterface>
    </joint>
    <actuator name="motor_hand_right">
      <mechanicalReduction>1</mechanicalReduction>
      <hardwareInterface>hardware_interface/EffortJointInterface</hardwareInterface>
    </actuator>
  </transmission>
  <transmission name="trans_body_hip">
    <type>transmission_interface/SimpleTransmission</type>
    <joint name="joint_body_hip">
      <hardwareInterface>hardware_interface/EffortJointInterface</hardwareInterface>
    </joint>
    <actuator name="motor_body_hip">
      <mechanicalReduction>1</mechanicalReduction>
      <hardwareInterface>hardware_interface/EffortJointInterface</hardwareInterface>
    </actuator>
  </transmission>-->
  <transmission name="trans_body_hip_left">
    <type>transmission_interface/SimpleTransmission</type>
    <joint name="joint_body_hip_left">
      <hardwareInterface>hardware_interface/EffortJointInterface</hardwareInterface>
    </joint>
    <actuator name="motor_body_hip_left">
      <mechanicalReduction>1</mechanicalReduction>
      <hardwareInterface>hardware_interface/EffortJointInterface</hardwareInterface>
    </actuator>
  </transmission>
  <transmission name="trans_body_hip2_left">
    <type>transmission_interface/SimpleTransmission</type>
    <joint name="joint_body_hip2_left">
      <hardwareInterface>hardware_interface/EffortJointInterface</hardwareInterface>
    </joint>
    <actuator name="motor_body_hip2_left">
      <mechanicalReduction>1</mechanicalReduction>
      <hardwareInterface>hardware_interface/EffortJointInterface</hardwareInterface>
    </actuator>
  </transmission>
  <transmission name="trans_leg_left">
    <type>transmission_interface/SimpleTransmission</type>
    <joint name="joint_leg_left">
      <hardwareInterface>hardware_interface/EffortJointInterface</hardwareInterface>
    </joint>
    <actuator name="motor_leg_left">
      <mechanicalReduction>1</mechanicalReduction>
      <hardwareInterface>hardware_interface/EffortJointInterface</hardwareInterface>
    </actuator>
  </transmission>
  <transmission name="trans_leg2_left">
    <type>transmission_interface/SimpleTransmission</type>
    <joint name="joint_leg2_left">
      <hardwareInterface>hardware_interface/EffortJointInterface</hardwareInterface>
    </joint>
    <actuator name="motor_leg2_left">
      <mechanicalReduction>1</mechanicalReduction>
      <hardwareInterface>hardware_interface/EffortJointInterface</hardwareInterface>
    </actuator>
  </transmission>
  <transmission name="trans_leg3_left">
    <type>transmission_interface/SimpleTransmission</type>
    <joint name="joint_leg3_left">
      <hardwareInterface>hardware_interface/EffortJointInterface</hardwareInterface>
    </joint>
    <actuator name="motor_leg3_left">
      <mechanicalReduction>1</mechanicalReduction>
      <hardwareInterface>hardware_interface/EffortJointInterface</hardwareInterface>
    </actuator>
  </transmission>
  <transmission name="trans_leg4_left">
    <type>transmission_interface/SimpleTransmission</type>
    <joint name="joint_leg4_left">
      <hardwareInterface>hardware_interface/EffortJointInterface</hardwareInterface>
    </joint>
    <actuator name="motor_leg4_left">
      <mechanicalReduction>1</mechanicalReduction>
      <hardwareInterface>hardware_interface/EffortJointInterface</hardwareInterface>
    </actuator>
  </transmission>
  <transmission name="trans_body_hip_right">
    <type>transmission_interface/SimpleTransmission</type>
    <joint name="joint_body_hip_right">
      <hardwareInterface>hardware_interface/EffortJointInterface</hardwareInterface>
    </joint>
    <actuator name="motor_body_hip_right">
      <mechanicalReduction>1</mechanicalReduction>
      <hardwareInterface>hardware_interface/EffortJointInterface</hardwareInterface>
    </actuator>
  </transmission>
  <transmission name="trans_body_hip2_right">
    <type>transmission_interface/SimpleTransmission</type>
    <joint name="joint_body_hip2_right">
      <hardwareInterface>hardware_interface/EffortJointInterface</hardwareInterface>
    </joint>
    <actuator name="motor_body_hip2_right">
      <mechanicalReduction>1</mechanicalReduction>
      <hardwareInterface>hardware_interface/EffortJointInterface</hardwareInterface>
    </actuator>
  </transmission>
  <transmission name="trans_leg_right">
    <type>transmission_interface/SimpleTransmission</type>
    <joint name="joint_leg_right">
      <hardwareInterface>hardware_interface/EffortJointInterface</hardwareInterface>
    </joint>
    <actuator name="motor_leg_right">
      <mechanicalReduction>1</mechanicalReduction>
      <hardwareInterface>hardware_interface/EffortJointInterface</hardwareInterface>
    </actuator>
  </transmission>
  <transmission name="trans_leg2_right">
    <type>transmission_interface/SimpleTransmission</type>
    <joint name="joint_leg2_right">
      <hardwareInterface>hardware_interface/EffortJointInterface</hardwareInterface>
    </joint>
    <actuator name="motor_leg2_right">
      <mechanicalReduction>1</mechanicalReduction>
      <hardwareInterface>hardware_interface/EffortJointInterface</hardwareInterface>
    </actuator>
  </transmission>
  <transmission name="trans_leg3_right">
    <type>transmission_interface/SimpleTransmission</type>
    <joint name="joint_leg3_right">
      <hardwareInterface>hardware_interface/EffortJointInterface</hardwareInterface>
    </joint>
    <actuator name="motor_leg3_right">
      <mechanicalReduction>1</mechanicalReduction>
      <hardwareInterface>hardware_interface/EffortJointInterface</hardwareInterface>
    </actuator>
  </transmission>
  <transmission name="trans_leg4_right">
    <type>transmission_interface/SimpleTransmission</type>
    <joint name="joint_leg4_right">
      <hardwareInterface>hardware_interface/EffortJointInterface</hardwareInterface>
    </joint>
    <actuator name="motor_leg4_right">
      <mechanicalReduction>1</mechanicalReduction>
      <hardwareInterface>hardware_interface/EffortJointInterface</hardwareInterface>
    </actuator>
  </transmission>
  <gazebo>
    <plugin name="gazebo_ros_control" filename="libgazebo_ros_control.so">
      <robotNamespace>/dancer_urdf_model</robotNamespace>
      <robotSimType>gazebo_ros_control/DefaultRobotHWSim</robotSimType>
    </plugin>
  </gazebo>
</robot>
